Workbook

Sheet SQL Server
B2: Costo licenza SQL Server | E2: 3560 | F2: (copre 2 core) | H2: al 23/04/2021

Sheet Backlog
A1: DATA | B1: NOTE | C1: Referente
A2: 46084 | B2: Aggiornati costi Licenze PostgreSQL ricevuti da Luca Conti nel tab ACN Listino licenze | C2: Daniele Celauro
A3: 46084 | B3: Sistemati errori nel tab Riepilogo Quadro Spese che non prendevano bene i costi dal tab Quadro Spese | C3: Daniele Celauro
A4: 46084 | B4: Nascosti alcuni tab informativi per semplificare la vista del file | C4: Daniele Celauro
A5: 46084 | B5: Inserito nel tab ACN Listino Licenze anche il costo delle licenze Premium di PostgreSQL | C5: Daniele Celauro
A6: 46085 | B6: Corretto errore nella somma dei component infrastrutturali nel tab ACN Costo Infra | C6: Daniele Celauro
A7: 46087 | B7: Aggiunta a Quadro Spese sezione per monitorare il consumo del budget quando il progetto va in execution | C7: Alessandro Liscio
A8: 46093 | B8: Sistemati i prezzi della gestione ACN impostando l'anno di riferimento. Sistemato il calcolo delle licenze Vmware Aggiornati alcuni prezzi di licenza software. Dubbi sulle licenze redhat, vmware, ocp | C8: Daniele Celauro
A9: 46108 | B9: Modificato taglio vcpu Worker a 16, eliminate righe Worker con taglio inferiore a 16vCPU | C9: Alessandro Liscio
A10: 46108 | B10: Aggiunte info tariffe PM a Tariffario | C10: Alessandro Liscio
A11: 46125 | B11: Rimossa riga Test Factory | C11: Alessandro Liscio
A12: 46126 | B12: Aggiunte info relative a iva a sheet Tariffario | C12: Alessandro Liscio
A13: 46127 | B13: Aggiunti i costi di Dynatrace | C13: Celauro/Malberti

Sheet ACN Costo Infra
A1: Device e/o servizi | B1: OPEX | C1: Caratteristiche | F1: Modello (ove disponibile) | I1: Costo Anno 1 | J1: Costo Anno 2 | K1: Costo Anno 3 | L1: Costo Anno 4 | M1: Costo Anno 5 | N1: Costo Anno 6 | O1: TOTALE | Q1: IVA | R1: 1.22
B2: o | C2: CPU | D2: RAM | E2: Tera | G2: peso | H2: Quantità
B3: CAPEX | E3: byte
A4: Catalogo Componenti Infrastrutturali
A5: Server virtuale - 4 vCore - Generic | B5: OPEX | C5: 4 | D5: 16 | F5: Senza OS, senza Vmware | H5: 0 | I5: =ACN!H4*'ACN Costo Infra'!$H$5*$R$1 -> 0 | J5: =ACN!I4*'ACN Costo Infra'!$H$5*$R$1 -> 0 | K5: =ACN!J4*'ACN Costo Infra'!$H$5*$R$1 -> 0 | L5: =ACN!K4*'ACN Costo Infra'!$H$5*$R$1 -> 0 | M5: =ACN!L4*'ACN Costo Infra'!$H$5*$R$1 -> 0 | N5: =ACN!M4*'ACN Costo Infra'!$H$5*$R$1 -> 0 | O5: =SUM(I5:N5) -> 0
A6: Server virtuale - 8 vCore - Generic | B6: OPEX | C6: 8 | D6: 32 | F6: Senza OS, senza Vmware | H6: 0 | I6: =ACN!H5*'ACN Costo Infra'!$H$6*$R$1 -> 0 | J6: =ACN!I5*'ACN Costo Infra'!$H$6*$R$1 -> 0 | K6: =ACN!J5*'ACN Costo Infra'!$H$6*$R$1 -> 0 | L6: =ACN!K5*'ACN Costo Infra'!$H$6*$R$1 -> 0 | M6: =ACN!L5*'ACN Costo Infra'!$H$6*$R$1 -> 0 | N6: =ACN!M5*'ACN Costo Infra'!$H$6*$R$1 -> 0 | O6: =SUM(I6:N6) -> 0
A7: Worker - 16 vCore - No Prod | B7: OPEX | C7: 16 | D7: 32 | F7: Senza OS, senza Vmware | H7: 1 | I7: =ACN!H5*'ACN Costo Infra'!$H$7*$R$1 -> 1051.7376 | J7: =ACN!I5*'ACN Costo Infra'!$H$7*$R$1 -> 972.706 | K7: =ACN!J5*'ACN Costo Infra'!$H$7*$R$1 -> 926.8096 | L7: =ACN!K5*'ACN Costo Infra'!$H$7*$R$1 -> 898.3958 | M7: =ACN!L5*'ACN Costo Infra'!$H$7*$R$1 -> 884.805 | N7: =ACN!M5*'ACN Costo Infra'!$H$7*$R$1 -> 884.805 | O7: =SUM(I7:N7) -> 5619.259
A8: Worker - 16 vCore - Prod | B8: OPEX | C8: 16 | D8: 32 | F8: Senza OS, senza Vmware | H8: 2 | I8: =ACN!H5*'ACN Costo Infra'!$H$8*$R$1 -> 2103.4752 | J8: =ACN!I5*'ACN Costo Infra'!$H$8*$R$1 -> 1945.412 | K8: =ACN!J5*'ACN Costo Infra'!$H$8*$R$1 -> 1853.6192 | L8: =ACN!K5*'ACN Costo Infra'!$H$8*$R$1 -> 1796.7916 | M8: =ACN!L5*'ACN Costo Infra'!$H$8*$R$1 -> 1769.61 | N8: =ACN!M5*'ACN Costo Infra'!$H$8*$R$1 -> 1769.61 | O8: =SUM(I8:N8) -> 11238.518
A9: Backup – Front-end | B9: OPEX | E9: 1 | F9: Uguale a storage PROD | H9: 2.2 | I9: =ACN!H6*'ACN Costo Infra'!$H$9*$R$1 -> 5862.9833 | J9: =ACN!I6*'ACN Costo Infra'!$H$9*S1 -> 0 | K9: =ACN!J6*'ACN Costo Infra'!$H$9*T1 -> 0 | L9: =ACN!K6*'ACN Costo Infra'!$H$9*U1 -> 0 | M9: =ACN!L6*'ACN Costo Infra'!$H$9*V1 -> 0 | N9: =ACN!M6*'ACN Costo Infra'!$H$9*W1 -> 0 | O9: =SUM(I9:N9) -> 5862.9833
A10: Backup – Back-end | B10: OPEX | E10: 1 | F10: Uguale a storage * 5 | H10: 11 | I10: =ACN!H7*'ACN Costo Infra'!$H$10*R1 -> 2704.801 | J10: =ACN!I7*'ACN Costo Infra'!$H$10*S1 -> 0 | K10: =ACN!J7*'ACN Costo Infra'!$H$10*T1 -> 0 | L10: =ACN!K7*'ACN Costo Infra'!$H$10*U1 -> 0 | M10: =ACN!L7*'ACN Costo Infra'!$H$10*V1 -> 0 | N10: =ACN!M7*'ACN Costo Infra'!$H$10*W1 -> 0 | O10: =SUM(I10:N10) -> 2704.801
A11: Storage - SSD | B11: OPEX | E11: 1 | F11: Replicato | H11: 0 | I11: =ACN!H8*'ACN Costo Infra'!$H$11*$R$1 -> 0 | J11: =ACN!I8*'ACN Costo Infra'!$H$11*S1 -> 0 | K11: =ACN!J8*'ACN Costo Infra'!$H$11*T1 -> 0 | L11: =ACN!K8*'ACN Costo Infra'!$H$11*U1 -> 0 | M11: =ACN!L8*'ACN Costo Infra'!$H$11*V1 -> 0 | N11: =ACN!M8*'ACN Costo Infra'!$H$11*W1 -> 0 | O11: =SUM(I11:N11) -> 0
A12: Storage - SSD non replicati | B12: OPEX | E12: 1 | F12: Non replicato | H12: 0 | I12: =ACN!H9*'ACN Costo Infra'!$H$12*R1 -> 0 | J12: =ACN!I9*'ACN Costo Infra'!$H$12*S1 -> 0 | K12: =ACN!J9*'ACN Costo Infra'!$H$12*T1 -> 0 | L12: =ACN!K9*'ACN Costo Infra'!$H$12*U1 -> 0 | M12: =ACN!L9*'ACN Costo Infra'!$H$12*V1 -> 0 | N12: =ACN!M9*'ACN Costo Infra'!$H$12*W1 -> 0 | O12: =SUM(I12:N12) -> 0
A13: Database Oracle (non RAC) - gestione istanze | B13: OPEX | F13: Operation - management DBMS instance | H13: 0 | I13: =ACN!H11*'ACN Costo Infra'!$H$13*R1 -> 0 | J13: =ACN!I11*'ACN Costo Infra'!$H$13*S1 -> 0 | K13: =ACN!J11*'ACN Costo Infra'!$H$13*T1 -> 0 | L13: =ACN!K11*'ACN Costo Infra'!$H$13*U1 -> 0 | M13: =ACN!L11*'ACN Costo Infra'!$H$13*V1 -> 0 | N13: =ACN!M11*'ACN Costo Infra'!$H$13*W1 -> 0 | O13: =SUM(I13:N13) -> 0
A14: Database Ms SQL - gestione istanze | B14: OPEX | F14: Operation - management DBMS instance | H14: 0 | I14: =ACN!H12*'ACN Costo Infra'!$H$14*R1 -> 0 | J14: =ACN!I12*'ACN Costo Infra'!$H$14*S1 -> 0 | K14: =ACN!J12*'ACN Costo Infra'!$H$14*T1 -> 0 | L14: =ACN!K12*'ACN Costo Infra'!$H$14*U1 -> 0 | M14: =ACN!L12*'ACN Costo Infra'!$H$14*V1 -> 0 | N14: =ACN!M12*'ACN Costo Infra'!$H$14*W1 -> 0 | O14: =SUM(I14:N14) -> 0
A15: DB2 Blu - gestione istanze | B15: OPEX | F15: Operation - management DBMS instance | H15: 0 | I15: =ACN!H13*'ACN Costo Infra'!$H$15*R1 -> 0 | J15: =ACN!I13*'ACN Costo Infra'!$H$15*S1 -> 0 | K15: =ACN!J13*'ACN Costo Infra'!$H$15*T1 -> 0 | L15: =ACN!K13*'ACN Costo Infra'!$H$15*U1 -> 0 | M15: =ACN!L13*'ACN Costo Infra'!$H$15*V1 -> 0 | N15: =ACN!M13*'ACN Costo Infra'!$H$15*W1 -> 0 | O15: =SUM(I15:N15) -> 0
A16: NoSQLDB - gestione istanze | B16: OPEX | F16: Operation - management DBMS instance | H16: 0 | I16: =ACN!H14*'ACN Costo Infra'!$H$16*R1 -> 0 | J16: =ACN!I14*'ACN Costo Infra'!$H$16*S1 -> 0 | K16: =ACN!J14*'ACN Costo Infra'!$H$16*T1 -> 0 | L16: =ACN!K14*'ACN Costo Infra'!$H$16*U1 -> 0 | M16: =ACN!L14*'ACN Costo Infra'!$H$16*V1 -> 0 | N16: =ACN!M14*'ACN Costo Infra'!$H$16*W1 -> 0 | O16: =SUM(I16:N16) -> 0
A17: Middleware IIS / Apache - gestione istanze | B17: OPEX | F17: Operation - management Middleware instance | H17: 0 | I17: =ACN!H15*'ACN Costo Infra'!$H$17*R1 -> 0 | J17: =ACN!I15*'ACN Costo Infra'!$H$17*S1 -> 0 | K17: =ACN!J15*'ACN Costo Infra'!$H$17*T1 -> 0 | L17: =ACN!K15*'ACN Costo Infra'!$H$17*U1 -> 0 | M17: =ACN!L15*'ACN Costo Infra'!$H$17*V1 -> 0 | N17: =ACN!M15*'ACN Costo Infra'!$H$17*W1 -> 0 | O17: =SUM(I17:N17) -> 0
A18: Middleware Tomcat/Jboss - gestione istanze | B18: OPEX | F18: Operation - management Middleware instance | H18: 0 | I18: =ACN!H16*'ACN Costo Infra'!$H$18*R1 -> 0 | J18: =ACN!I16*'ACN Costo Infra'!$H$18*S1 -> 0 | K18: =ACN!J16*'ACN Costo Infra'!$H$18*T1 -> 0 | L18: =ACN!K16*'ACN Costo Infra'!$H$18*U1 -> 0 | M18: =ACN!L16*'ACN Costo Infra'!$H$18*V1 -> 0 | N18: =ACN!M16*'ACN Costo Infra'!$H$18*W1 -> 0 | O18: =SUM(I18:N18) -> 0
A19: Middleware WebSphere - gestione istanze | B19: OPEX | F19: Operation - management Middleware instance | H19: 0 | I19: =ACN!H17*'ACN Costo Infra'!$H$19*R1 -> 0 | J19: =ACN!I17*'ACN Costo Infra'!$H$19*S1 -> 0 | K19: =ACN!J17*'ACN Costo Infra'!$H$19*T1 -> 0 | L19: =ACN!K17*'ACN Costo Infra'!$H$19*U1 -> 0 | M19: =ACN!L17*'ACN Costo Infra'!$H$19*V1 -> 0 | N19: =ACN!M17*'ACN Costo Infra'!$H$19*W1 -> 0 | O19: =SUM(I19:N19) -> 0
A20: Middleware WebLogic - gestione istanze | B20: OPEX | F20: Operation - management Middleware instance | H20: 0 | I20: =ACN!H18*'ACN Costo Infra'!$H$20*R1 -> 0 | J20: =ACN!I18*'ACN Costo Infra'!$H$20*S1 -> 0 | K20: =ACN!J18*'ACN Costo Infra'!$H$20*T1 -> 0 | L20: =ACN!K18*'ACN Costo Infra'!$H$20*U1 -> 0 | M20: =ACN!L18*'ACN Costo Infra'!$H$20*V1 -> 0 | N20: =ACN!M18*'ACN Costo Infra'!$H$20*W1 -> 0 | O20: =SUM(I20:N20) -> 0
A21: Middleware Kubernetes - gestione Pod Deployment | B21: OPEX | F21: Numero Pod Deployment moltiplicato per ogni ambiente rilasciato | H21: 3 | I21: =$H$21*ACN!L20*R1 -> 918.66 | J21: =$H$21*ACN!I20*R1 -> 918.66 | K21: =$H$21*ACN!J20*R1 -> 918.66 | L21: =$H$21*ACN!K20*R1 -> 918.66 | M21: =$H$21*ACN!L20*R1 -> 918.66 | N21: =$H$21*ACN!M20*R1 -> 918.66 | O21: =SUM(I21:N21) -> 5511.96
A22: Middleware Kubernetes - gestione NameSpace | B22: OPEX | F22: Numero Namespace moltiplicato per ogni ambiente rilasciato | H22: 9 | I22: =$H$22*ACN!L21*R1 -> 5841.36 | J22: =$H$22*ACN!I21*R1 -> 5841.36 | K22: =$H$22*ACN!J21*R1 -> 5841.36 | L22: =$H$22*ACN!K21*R1 -> 5841.36 | M22: =$H$22*ACN!L21*R1 -> 5841.36 | N22: =$H$22*ACN!M21*R1 -> 5841.36 | O22: =SUM(I22:N22) -> 35048.16
A23: Oracle OCPU | B23: OPEX | F23: Numero di Ocpu richieste per progetto (Ocpu) | H23: 0 | I23: =$H$23*ACN!L22*$R$1/2 -> 0 | J23: =$H$23*ACN!I22*$R$1/2 -> 0 | K23: =$H$23*ACN!J22*$R$1/2 -> 0 | L23: =$H$23*ACN!K22*$R$1/2 -> 0 | M23: =$H$23*ACN!L22*$R$1/2 -> 0 | N23: =$H$23*ACN!M22*$R$1/2 -> 0 | O23: =SUM(I23:N23) -> 0
A24: Oracle STORAGE | B24: OPEX | F24: Numero di storage oracle per progetto (Tera) | H24: 0 | I24: =$H$24*ACN!L23*$R$1/30 -> 0 | J24: =$H$24*ACN!I23*$R$1/30 -> 0 | K24: =$H$24*ACN!J23*$R$1/30 -> 0 | L24: =$H$24*ACN!K23*$R$1/30 -> 0 | M24: =$H$24*ACN!L23*$R$1/30 -> 0 | N24: =$H$24*ACN!M23*$R$1/30 -> 0 | O24: =SUM(I24:N24) -> 0
I25: Costo Anno 1 | J25: Costo Anno 2 | K25: Costo Anno 3 | L25: Costo Anno 4 | M25: Costo Anno 5 | N25: Costo Anno 6 | O25: TOTALE
A26: TOTALE RUNNING TIM/ACN | B26: OPEX | I26: =SUM(I5:I24) -> 18483.017 | J26: =SUM(J5:J24) -> 9678.138 | K26: =SUM(K5:K24) -> 9540.4488 | L26: =SUM(L5:L24) -> 9455.2074 | M26: =SUM(M5:M24) -> 9414.435 | N26: =SUM(N5:N24) -> 9414.435 | O26: =SUM(O5:O24) -> 65985.681
A27: Catalogo Licenze
A28: RED HAT | B28: OPEX | F28: RedHAt Sistema Operativo (somma core redhat no openshift, diviso 3) | G28: 0 | H28: 0 | I28: =H28*'ACN Listino licenze'!C41*R1 -> 0 | J28: =I28 -> 0 | K28: =I28 -> 0 | L28: =I28 -> 0 | M28: =I28 -> 0 | N28: =I28 -> 0 | O28: =SUM(I28:N28) -> 0
A29: JBOSS PREPROD | B29: OPEX | F29: N° core, licenza da 16 core | G29: 1 | H29: 0 | I29: ='ACN Listino licenze'!C25*G29*H29/16*$R$1 -> 0 | J29: ='ACN Listino licenze'!$E$25*$G$29*$H$29*$R$1/16 -> 0 | K29: ='ACN Listino licenze'!$E$25*$G$29*$H$29*$R$1/16 -> 0 | L29: ='ACN Listino licenze'!$E$25*$G$29*$H$29*$R$1/16 -> 0 | M29: ='ACN Listino licenze'!$E$25*$G$29*$H$29*$R$1/16 -> 0 | N29: ='ACN Listino licenze'!$E$25*$G$29*$H$29*$R$1/16 -> 0 | O29: =SUM(I29:N29) -> 0
A30: JBOSS PROD | B30: OPEX | F30: N° core, licenza da 16 core | G30: 1 | H30: 0 | I30: =G30*H30*'ACN Listino licenze'!C26/16*R1 -> 0 | J30: =$G$30*$H$30*'ACN Listino licenze'!$E$26*$R$1/16 -> 0 | K30: =$G$30*$H$30*'ACN Listino licenze'!$E$26*$R$1/16 -> 0 | L30: =$G$30*$H$30*'ACN Listino licenze'!$E$26*$R$1/16 -> 0 | M30: =$G$30*$H$30*'ACN Listino licenze'!$E$26*$R$1/16 -> 0 | N30: =$G$30*$H$30*'ACN Listino licenze'!$E$26*$R$1/16 -> 0 | O30: =SUM(I30:N30) -> 0
A31: Websphere PREPROD | B31: CAPEX | F31: LICENZA PER PVU (1 pvu 70*N.TOT CORE DEL SERVER FISICO) -inserire nel campo quantità il numero dei core del server fisico o 0 | G31: 1 | H31: 0 | I31: =$G$31*$H$31*'ACN Listino licenze'!C27*70*R1 -> 0 | J31: =$G$31*$H$31*'ACN Listino licenze'!$E$27*70*R$1 -> 0 | K31: =$G$31*$H$31*'ACN Listino licenze'!$E$27*70*S$1 -> 0 | L31: =$G$31*$H$31*'ACN Listino licenze'!$E$27*70*T$1 -> 0 | M31: =$G$31*$H$31*'ACN Listino licenze'!$E$27*70*U$1 -> 0 | N31: =$G$31*$H$31*'ACN Listino licenze'!$E$27*70*V$1 -> 0 | O31: =SUM(I31:N31) -> 0
A32: Websphere PROD | B32: CAPEX | F32: LICENZA PER PVU (1 pvu 70*N.TOT CORE DEL SERVER FISICO) -inserire nel campo quantità il numero dei core del server fisico o 0 | G32: 1 | H32: 0 | I32: ='ACN Listino licenze'!C27*H32*G32*70*R1 -> 0 | J32: =$G$32*$H$32*'ACN Listino licenze'!$E$27*70*$R$1 -> 0 | K32: =$G$32*$H$32*'ACN Listino licenze'!$E$27*70*$R$1 -> 0 | L32: =$G$32*$H$32*'ACN Listino licenze'!$E$27*70*$R$1 -> 0 | M32: =$G$32*$H$32*'ACN Listino licenze'!$E$27*70*$R$1 -> 0 | N32: =$G$32*$H$32*'ACN Listino licenze'!$E$27*70*$R$1 -> 0 | O32: =SUM(I32:N32) -> 0
A33: TWS PER JOB | B33: CAPEX | F33: N. JOB ESEGUITI IN UN MESE | G33: 1 | H33: 0 | I33: =G33*H33*'ACN Listino licenze'!C36*$R$1 -> 0 | J33: =$G$33*$H$33*'ACN Listino licenze'!$E$36*$R$1 -> 0 | K33: =$G$33*$H$33*'ACN Listino licenze'!$E$36*$R$1 -> 0 | L33: =$G$33*$H$33*'ACN Listino licenze'!$E$36*$R$1 -> 0 | M33: =$G$33*$H$33*'ACN Listino licenze'!$E$36*$R$1 -> 0 | N33: =$G$33*$H$33*'ACN Listino licenze'!$E$36*$R$1 -> 0 | O33: =SUM(I33:N33) -> 0
A34: Vmware (89 euro per core per anno, numero core virtuali /3) | B34: OPEX | F34: N. DI CORE ( costo per Core FISICO- stima 3 core virtuali=1core Fisico) | H34: =(H5*4+H6*8)/3+(H7*16+H8*16)/3 -> 16 | I34: =$H$34*89*1.05*1.006*1.22 -> 1835.0889 | J34: =$H$34*110*1.05*1.006*1.22 -> 2268.0874 | K34: =$H$34*110*1.05*1.006*1.22 -> 2268.0874 | L34: =$H$34*110*1.05*1.006*1.22 -> 2268.0874 | M34: =$H$34*110*1.05*1.006*1.22 -> 2268.0874 | N34: =$H$34*110*1.05*1.006*1.22 -> 2268.0874 | O34: =SUM(I34:N34) -> 13175.526
A35: SRM Prod | B35: CAPEX | F35: N. MACCHINE VIRTUALI | G35: 1 | H35: 0 | I35: ='ACN Listino licenze'!C39/25*H35*G35*1.22 -> 0 | J35: ='ACN Listino licenze'!$E$39*$G$35*$H$35/25*1.22 -> 0 | K35: ='ACN Listino licenze'!$E$39*$G$35*$H$35/25*1.22 -> 0 | L35: ='ACN Listino licenze'!$E$39*$G$35*$H$35/25*1.22 -> 0 | M35: ='ACN Listino licenze'!$E$39*$G$35*$H$35/25*1.22 -> 0 | N35: ='ACN Listino licenze'!$E$39*$G$35*$H$35/25*1.22 -> 0 | O35: =SUM(I35:N35) -> 0
A36: Mirantis - Prod | B36: OPEX | F36: N. DI CORE ( costo per Core) | G36: 1 | H36: 0 | I36: =G36*H36*'ACN Listino licenze'!C46*$R$1 -> 0 | J36: =I36 -> 0 | K36: =J36 -> 0 | L36: =K36 -> 0 | M36: =L36 -> 0 | N36: =M36 -> 0 | O36: =SUM(I36:N36) -> 0
A37: Mirantis - DR | B37: OPEX | F37: N. DI CORE ( costo per Core) | G37: 1 | H37: 0 | I37: =G37*H37*'ACN Listino licenze'!C47*$R$1 -> 0 | J37: =I37 -> 0 | K37: =J37 -> 0 | L37: =K37 -> 0 | M37: =L37 -> 0 | N37: =M37 -> 0 | O37: =SUM(I37:N37) -> 0
A38: Mirantis - PreProd | B38: OPEX | F38: N. DI CORE ( costo per Core) | G38: 1 | H38: 0 | I38: =G38*H38*'ACN Listino licenze'!C48*$R$1 -> 0 | J38: =I38 -> 0 | K38: =J38 -> 0 | L38: =K38 -> 0 | M38: =L38 -> 0 | N38: =M38 -> 0 | O38: =SUM(I38:N38) -> 0
A39: OpenShift - Prod | B39: OPEX | F39: N. DI CORE ( costo per Core) | G39: 1 | H39: 19 | I39: =G39*H39*'ACN Listino licenze'!C49*$R$1 -> 16014.367 | J39: =I39 -> 16014.367 | K39: =J39 -> 16014.367 | L39: =K39 -> 16014.367 | M39: =L39 -> 16014.367 | N39: =M39 -> 16014.367 | O39: =SUM(I39:N39) -> 96086.2
A40: OpenShift - DR 1 core | B40: OPEX | F40: N. DI CORE ( costo per Core) | G40: 1 | H40: 19 | I40: =G40*H40*'ACN Listino licenze'!C50*$R$1 -> 10771.514 | J40: =I40 -> 10771.514 | K40: =J40 -> 10771.514 | L40: =K40 -> 10771.514 | M40: =L40 -> 10771.514 | N40: =M40 -> 10771.514 | O40: =SUM(I40:N40) -> 64629.085
...

Sheet ACN Riepilogo Costo Infra
A1: Impatto Progettuale anno 2026 su 12 mesi
A2: Riepilogo | B2: Tipologia | C2: Impatto RUN Progettuale | D2: Costi Ricorsivi Anni Successivi | F2: Mesi progetto
A3: Totale Attività Progettuali Investimento | B3: CAPEX | C3: ='ACN Costo Infra'!I69 -> 0 | F3: 6
A4: Totale Oneri One-Off | B4: OPEX | C4: ='ACN Costo Infra'!I70 -> 0
A5: TOTALE Licenze Investimento | B5: CAPEX | C5: ='ACN Costo Infra'!I55 -> 0
A6: Totale Licenze Dynatrace OPEX | B6: OPEX | C6: ='ACN Costo Infra'!I56 -> 2064.3156 | D6: ='ACN Costo Infra'!J56 -> 2064.3156
A7: Totale Licenze OPEX | B7: OPEX | C7: ='ACN Costo Infra'!I57 -> 37124.797 | D7: ='ACN Costo Infra'!J57 -> 37915.901
A8: TOTALE RUNNING TIM/ACN | B8: OPEX | C8: ='ACN Costo Infra'!I26 -> 18483.017 | D8: ='ACN Costo Infra'!J26 -> 9678.138
A9: TOTALE RUNNING ACN CLOUD | B9: OPEX | C9: ='ACN Costo Infra'!I94 -> 0 | D9: ='ACN Costo Infra'!J94 -> 0
A11: TOTALE IVA INCLUSA | C11: =SUM(C3:C8) -> 57672.129 | D11: =SUM(D6:D10) -> 49658.354
A13: Impatto Progettuale anno 2026 sui mesi di progetto
A14: Riepilogo | B14: Tipologia | C14: Impatto RUN Progettuale | D14: Costi Ricorsivi Anni Successivi
A15: Totale Attività Progettuali Investimento | B15: CAPEX | C15: =C3 -> 0
A16: Totale Oneri One-Off | B16: OPEX | C16: =C4 -> 0
A17: TOTALE Licenze Investimento | B17: CAPEX | C17: =C5 -> 0
A18: Totale Licenze Dynatrace OPEX | B18: OPEX | C18: =(C6/12)*$F$3 -> 1032.1578 | D18: =D6 -> 2064.3156
A19: Totale Licenze OPEX | B19: OPEX | C19: =(C7/12)*$F$3 -> 18562.398 | D19: =D7 -> 37915.901
A20: TOTALE RUNNING TIM/ACN | B20: OPEX | C20: =(C8/12)*$F$3 -> 9241.5085 | D20: =D8 -> 9678.138
A21: TOTALE RUNNING ACN CLOUD | B21: OPEX | C21: =(C9/12)*$F$3 -> 0 | D21: =D9 -> 0
A23: TOTALE IVA INCLUSA | C23: =SUM(C15:C21) -> 28836.065 | D23: =SUM(D15:D21) -> 49658.354

Sheet Quadro Spese
B1: Anno | G1: Tipologia Costo | H1: Budget complessivo Progetto | I1: Budget CTO | J1: Allocazione Budget CTO su Budget complessivo Progetto | K1: Richieste fondi | L1: Offerte | M1: Delta (Budget CTO - Richieste Fondi) | N1: Macro attività | O1: Budget Consigliato | P1: Budget Stimato | Q1: Delta Stimato vs Consigliato | R1: % distribuzione task Stimato | S1: % distribuzione task (ORIG) | T1: Delta | V1: % distribuzione task Consigliato | W1: % Delta Actual vs. Consigliato | X1: Budget Consumato | Y1: Budget Residuo
B2: 2026 | G2: capEx | H2: 100000 | I2: 100000 | J2: =I2/H2 -> 1 | K2: =SUMIFS(Z18:Z28,K18:K28,G2,C18:C28,C17) -> 0 | L2: =SUMIFS(Z18:Z28,K18:K28,G2,B18:B28,B17) -> 0 | M2: =I2-K2 -> 100000 | N2: Governance | O2: =$I$2*V2 -> 5000 | P2: =SUMIFS(Z$18:Z$35,K$18:K$35,$G$2,I$18:I$35,N2,P$18:P$35,"Stima") -> 0 | Q2: =O2-P2 -> 5000 | R2: =P2/$I$2 -> 0 | S2: 0.1 | T2: =R2-S2 -> -0.1 | V2: 0.05 | W2: =R2-V2 -> -0.05 | X2: =SUMIFS(Z$18:Z$35,K$18:K$35,$G$2,I$18:I$35,N2,P$18:P$35,"Richiesta Fondi") -> 0 | Y2: =P2-X2 -> 0
N3: Provisioning-Configuration | O3: =$I$2*V3 -> 20000 | P3: =SUMIFS(Z$18:Z$35,K$18:K$35,$G$2,I$18:I$35,N3,P$18:P$35,"Stima") -> 15347.6 | Q3: =O3-P3 -> 4652.4 | R3: =P3/$I$2 -> 0.153476 | S3: 0.3 | T3: =R3-S3 -> -0.146524 | V3: 0.2 | W3: =R3-V3 -> -0.046524 | X3: =SUMIFS(Z$18:Z$35,K$18:K$35,$G$2,I$18:I$35,N3,P$18:P$35,"Richiesta Fondi") -> 0 | Y3: =P3-X3 -> 15347.6
N4: QA | O4: =$I$2*V4 -> 25000 | P4: =SUMIFS(Z$18:Z$35,K$18:K$35,$G$2,I$18:I$35,N4,P$18:P$35,"Stima") -> 27450 | Q4: =O4-P4 -> -2450 | R4: =P4/$I$2 -> 0.2745 | S4: 0.15 | T4: =R4-S4 -> 0.1245 | V4: 0.25 | W4: =R4-V4 -> 0.0245 | X4: =SUMIFS(Z$18:Z$35,K$18:K$35,$G$2,I$18:I$35,N4,P$18:P$35,"Richiesta Fondi") -> 0 | Y4: =P4-X4 -> 27450
N5: Load Test | O5: =$I$2*V5 -> 25000 | P5: =SUMIFS(Z$18:Z$35,K$18:K$35,$G$2,I$18:I$35,N5,P$18:P$35,"Stima") -> 32208 | Q5: =O5-P5 -> -7208 | R5: =P5/$I$2 -> 0.32208 | V5: 0.25 | W5: =R5-V5 -> 0.07208 | X5: =SUMIFS(Z$18:Z$35,K$18:K$35,$G$2,I$18:I$35,N5,P$18:P$35,"Richiesta Fondi") -> 0 | Y5: =P5-X5 -> 32208
N6: Observability | O6: =$I$2*V6 -> 10000 | P6: =SUMIFS(Z$18:Z$35,K$18:K$35,$G$2,I$18:I$35,N6,P$18:P$35,"Stima") -> 8662 | Q6: =O6-P6 -> 1338 | R6: =P6/$I$2 -> 0.08662 | S6: 0.07 | T6: =R6-S6 -> 0.01662 | V6: 0.1 | W6: =R6-V6 -> -0.01338 | X6: =SUMIFS(Z$18:Z$35,K$18:K$35,$G$2,I$18:I$35,N6,P$18:P$35,"Richiesta Fondi") -> 0 | Y6: =P6-X6 -> 8662
N7: DevOps | O7: =$I$2*V7 -> 10000 | P7: =SUMIFS(Z$18:Z$35,K$18:K$35,$G$2,I$18:I$35,N7,P$18:P$35,"Stima") -> 0 | Q7: =O7-P7 -> 10000 | R7: =P7/$I$2 -> 0 | S7: 0.07 | T7: =R7-S7 -> -0.07 | V7: 0.1 | W7: =R7-V7 -> -0.1 | X7: =SUMIFS(Z$18:Z$35,K$18:K$35,$G$2,I$18:I$35,N7,P$18:P$35,"Richiesta Fondi") -> 0 | Y7: =P7-X7 -> 0
N8: RFC | O8: =$I$2*V8 -> 5000 | P8: =SUMIFS(Z$18:Z$35,K$18:K$35,$G$2,I$18:I$35,N8,P$18:P$35,"Stima") -> 7808 | Q8: =O8-P8 -> -2808 | R8: =P8/$I$2 -> 0.07808 | S8: 0.05 | T8: =R8-S8 -> 0.02808 | V8: 0.05 | W8: =R8-V8 -> 0.02808 | X8: =SUMIFS(Z$18:Z$35,K$18:K$35,$G$2,I$18:I$35,N8,P$18:P$35,"Richiesta Fondi") -> 0 | Y8: =P8-X8 -> 7808
P9: =SUM(P2:P8) -> 91475.6 | R9: =SUM(R2:R8) -> 0.914756 | V9: =SUM(V2:V8) -> 1 | Y9: =SUM(Y2:Y8) -> 91475.6
O10: =IF(SUM(O2:O8)=I2,"Check somma allocato per macroattività","KO") -> Check somma allocato per macroattività | P10: =IF(SUM(P2:P8)=K2,"Singole richieste fondi OK","Da verificare richieste fondi") -> Da verificare richieste fondi
G11: opEx | H11: 100000 | I11: 40000 | J11: =I11/H11 -> 0.4 | K11: =SUMIFS(Z18:Z28,K18:K28,G11,C18:C28,C17) -> 0 | L11: =SUMIFS(Z18:Z28,K18:K28,G11,B18:B28,B17) -> 0 | M11: =I11-K11 -> 40000 | N11: Subscription | O11: - | P11: =SUMIFS(Z$18:Z$35,K$18:K$35,$G$11,I$18:I$35,N11,P$18:P$35,"Stima") -> 19594.556 | Q11: - | R11: =P11/$I$11 -> 0.4898639 | X11: =SUMIFS(Z$18:Z$35,K$18:K$35,$G$11,I$18:I$35,N11,P$18:P$35,"Richiesta Fondi") -> 0 | Y11: =P11-X11 -> 19594.556
N12: DC | O12: - | P12: =SUMIFS(Z$18:Z$35,K$18:K$35,$G$11,I$18:I$35,N12,P$18:P$35,"Stima") -> 9241.5085 | Q12: - | R12: =P12/$I$11 -> 0.23103771 | X12: =SUMIFS(Z$18:Z$35,K$18:K$35,$G$11,I$18:I$35,N12,P$18:P$35,"Richiesta Fondi") -> 0 | Y12: =P12-X12 -> 9241.5085
N13: RFC | O13: - | P13: =SUMIFS(Z$18:Z$35,K$18:K$35,$G$11,I$18:I$35,N13,P$18:P$35,"Stima") -> 0 | Q13: - | R13: =P13/$I$11 -> 0 | X13: =SUMIFS(Z$18:Z$35,K$18:K$35,$G$11,I$18:I$35,N13,P$18:P$35,"Richiesta Fondi") -> 0 | Y13: =P13-X13 -> 0
P14: =SUM(P11:P13) -> 28836.065 | R14: =SUM(R11:R13) -> 0.72090162 | Y14: =SUM(Y11:Y13) -> 28836.065
O15: =IF(SUM(O11:O13)=I11,"Check somma allocato per macroattività","KO") -> KO | P15: =IF(SUM(P11:P13)=K11,"Singole richieste fondi OK","Da verificare richieste fondi") -> Da verificare richieste fondi | T15: =630*500 -> 315000
A17: AQ | B17: OF | C17: RCF | D17: RDA | E17: AUTH | F17: ORDINE | G17: Data ricezione proposta / approvazione rich. Fondi | H17: Fornitore | I17: Macro attività | J17: Descrizione attività | K17: CAPEX / OPEX | L17: Quarter in cui spesare l'attività | M17: Data inizio attività | N17: Data fine attività | O17: Ambito | P17: Tipologia | Q17: NR. FTE | R17: % Allocazione | S17: Colonna3 | T17: Colonna4 | U17: Colonna5 | V17: Numero Mesi | W17: GG. Lavorativi | X17: Quotazione giornaliera | Y17: Importo i.e. | Z17: Importo i.i | AA17: Accordo Quadro Y / N | AB17: ID Richiesta fondi | AC17: ID RdA | AD17: Gara Y/N | AE17: Note
A18: wait | B18: wait | C18: wait | D18: wait | E18: wait | F18: wait | H18: Imola Informatica | I18: Provisioning-Configuration | J18: Realizzazione delle Pipeline e Supporto al DEV/OPS | K18: CAPEX | L18: giugno - luglio | M18: 46174 | N18: 21/7/2026 | O18: Infrastrutture | P18: Stima | Q18: 1 | W18: 20 | X18: 930 | Y18: =Tariffario!E37 -> 12580 | Z18: =Tabella13[[#This Row],[Importo i.e.]]*1.22 -> 15347.6
A19: wait | B19: wait | C19: wait | D19: wait | E19: wait | F19: wait | I19: QA | J19: Quality Assurance all’interno del progetto --> verifica qualità del SW - Verifica DR - Observability - Security (Istio Policy, Encryption, Vulnerability) - DevOps - Design e Code Review - Architecture Compliance - Infrastructure Compliance - Testing e UAT | K19: CAPEX | L19: giugno - dicembre | M19: 46174 | N19: 31/12/2026 | O19: Infrastrutture | P19: Stima | Q19: 1 | R19: 0.25 | V19: 6 | W19: 20 | X19: 750 | Y19: =ROUNDUP(Q19*R19*V19*W19*X19,-2) -> 22500 | Z19: =Tabella13[[#This Row],[Importo i.e.]]*1.22 -> 27450
A20: wait | B20: wait | C20: wait | D20: wait | E20: wait | F20: wait | I20: Load Test | J20: Definizione, esecuzione e valutazione dei load test | K20: CAPEX | L20: settembre - dicembre | M20: 46266 | N20: 01/012/2026 | O20: Infrastrutture | P20: Stima | Q20: 2 | R20: 1 | V20: 2 | W20: 20 | X20: 330 | Y20: =ROUNDUP(Q20*R20*V20*W20*X20,-2) -> 26400 | Z20: =Tabella13[[#This Row],[Importo i.e.]]*1.22 -> 32208
A21: wait | B21: wait | C21: wait | D21: wait | E21: wait | F21: wait | I21: Observability | J21: Estensione delle dashboard di observability | K21: CAPEX | L21: aprile - agosto | M21: 46113 | N21: 46235 | O21: Infrastrutture | P21: Stima | Q21: 1 | R21: 0.75 | V21: 1 | W21: 20 | X21: 470 | Y21: =ROUNDUP(Q21*R21*V21*W21*X21,-2) -> 7100 | Z21: =Tabella13[[#This Row],[Importo i.e.]]*1.22 -> 8662
A22: wait | B22: wait | C22: wait | D22: wait | E22: wait | F22: wait | I22: RFC | J22: Change Enablers | K22: CAPEX | L22: luglio - settembre | M22: 46204 | N22: 31/09/2026 | O22: Infrastrutture | P22: Stima | Q22: 1 | R22: 0.4 | V22: 2 | W22: 20 | X22: 400 | Y22: =ROUNDUP(Q22*R22*V22*W22*X22,-2) -> 6400 | Z22: =Tabella13[[#This Row],[Importo i.e.]]*1.22 -> 7808
A23: wait | B23: wait | C23: wait | D23: wait | E23: wait | F23: wait | I23: DevOps | J23: Pipeline DevOps | K23: CAPEX | L23: N/A | M23: 46174 | N23: 46327 | O23: Infrastrutture | P23: Stima | Q23: 1 | W23: 20 | X23: 420 | Y23: =ROUNDUP(Q23*R23*V23*W23*X23,-2) -> 0 | Z23: =Tabella13[[#This Row],[Importo i.e.]]*1.22 -> 0
A24: wait | B24: wait | C24: wait | D24: wait | E24: wait | F24: wait | H24: RedHat | I24: Subscription | J24: Tot. licenze Infra | K24: OPEX | L24: giugno - dicembre | M24: 46174 | N24: 46387 | O24: Infrastrutture | P24: Stima | Y24: ='ACN Riepilogo Costo Infra'!C19/1.22 -> 15215.081 | Z24: ='ACN Riepilogo Costo Infra'!C19 -> 18562.398
A25: wait | B25: wait | C25: wait | D25: wait | E25: wait | F25: wait | H25: Dynatrace | I25: Subscription | J25: Tot. licenze Dynatyrace | K25: OPEX | L25: giugno - dicembre | M25: 46174 | N25: 46387 | O25: Infrastrutture | P25: Stima | Y25: ='ACN Riepilogo Costo Infra'!C18/1.22 -> 846.031 | Z25: ='ACN Riepilogo Costo Infra'!C18 -> 1032.1578
A26: wait | B26: wait | C26: wait | D26: wait | E26: wait | F26: wait | I26: RFC | J26: Quota apertura / monitoring RFC | K26: OPEX | M26: 46176 | O26: Infrastrutture | P26: Stima | Y26: =ROUNDUP(Q26*R26*V26*W26*X26,-2) -> 0
A27: wait | B27: wait | C27: wait | D27: wait | E27: wait | F27: wait | I27: DC | J27: Canone running infrastruttura | K27: OPEX | L27: giugno - dicembre | M27: 46174 | N27: 46387 | O27: Infrastrutture | P27: Stima | Z27: ='ACN Riepilogo Costo Infra'!C20 -> 9241.5085
A28: wait | B28: wait | C28: wait | D28: wait | E28: wait | F28: wait | I28: DC | J28: Canone running infrastruttura Cloud | K28: OPEX | L28: febbraio - dicembre | M28: 46054 | N28: 46387 | O28: Infrastrutture | P28: Stima | Y28: =ROUNDUP(Q28*R28*V28*W28*X28,-2) -> 0

Sheet Riepilogo Quadro Spese
A1: capEx CTO Anno 2026
A2: Voce di Spesa | B2: Descrizione | C2: Importo i.i.
A3: ='Quadro Spese'!N2 -> Governance | B3: ='Quadro Spese'!#REF! -> #REF! | C3: ='Quadro Spese'!P2 -> 0
A4: ='Quadro Spese'!N3 -> Provisioning-Configuration | B4: ='Quadro Spese'!J18 -> Realizzazione delle Pipeline e Supporto al DEV/OPS | C4: ='Quadro Spese'!P3 -> 15347.6
A5: ='Quadro Spese'!N4 -> QA | B5: ='Quadro Spese'!J19 -> Quality Assurance all’interno del progetto --> verifica qualità del SW - Verifica DR - Observability - Security (Istio Policy, Encryption, Vulnerability) - DevOps - Design e Code Review - Architecture Compliance - Infrastructure Compliance - Testing e UAT | C5: ='Quadro Spese'!P4 -> 27450
A6: ='Quadro Spese'!N5 -> Load Test | B6: ='Quadro Spese'!J20 -> Definizione, esecuzione e valutazione dei load test | C6: ='Quadro Spese'!P5 -> 32208
A7: ='Quadro Spese'!N6 -> Observability | B7: ='Quadro Spese'!J21 -> Estensione delle dashboard di observability | C7: ='Quadro Spese'!P6 -> 8662
A8: ='Quadro Spese'!N7 -> DevOps | B8: - Pipeline DevOps | C8: ='Quadro Spese'!P7 -> 0
A9: ='Quadro Spese'!N8 -> RFC | B9: ='Quadro Spese'!J22 -> Change Enablers | C9: ='Quadro Spese'!P8 -> 7808
A10: Tot. | C10: =SUM(C3:C9) -> 91475.6
A12: opEx CTO Anno 2026
A13: Voce di Spesa | B13: Descrizione | C13: Importo i.i.
A14: ='Quadro Spese'!N11 -> Subscription | B14: ='Quadro Spese'!J24 -> Tot. licenze Infra | C14: ='Quadro Spese'!P11 -> 19594.556
A15: ='Quadro Spese'!N12 -> DC | B15: ='Quadro Spese'!J27 -> Canone running infrastruttura | C15: ='Quadro Spese'!P12 -> 9241.5085
A16: ='Quadro Spese'!N13 -> RFC | B16: ='Quadro Spese'!J26 -> Quota apertura / monitoring RFC | C16: ='Quadro Spese'!P13 -> 0
A17: Tot. | C17: =SUM(C14:C16) -> 28836.065

Sheet Tariffario
A1: Stess Test
A2: FTE | B2: Tariffa giornaliera i.e. | C2: Azienda | D2: GG | E2: Totale i.e.
A3: PM/Analista Funzionale / Specialist / Test manager | B3: 340 | C3: Sidesoft | D3: 5 | E3: =B3*D3 -> 1700
A4: Analista Tecnico / programmatore Senior / Test Analyst | B4: 320 | C4: Sidesoft | D4: 12.5 | E4: =B4*D4 -> 4000
A5: Programmatore / Tester | B5: 260 | C5: Sidesoft | D5: 0 | E5: =B5*D5 -> 0
E6: =SUM(E3:E5) -> 5700
A8: Observability (Dynatrace)
A9: FTE | B9: Tariffa giornaliera i.e. | C9: Azienda | D9: GG | E9: Totale i.e.
A10: OBSERVABILITY ENGINEER/SPECIALIST | B10: 450 | C10: Reply | D10: 13 | E10: =B10*D10 -> 5850
A11: OBSERVABILITY ARCHITECT | B11: 600 | C11: Reply | D11: 2 | E11: =B11*D11 -> 1200
E12: =SUM(E9:E11) -> 7050
A14: QA - NTT Data
A15: FTE | B15: Tariffa giornaliera i.e. | C15: Azienda | D15: GG | E15: Totale i.e.
A16: Architetto IT Senior | B16: 750 | C16: NTT Data | E16: =B16*D16 -> 0
A18: Governance PM
A19: FTE | B19: Tariffa giornaliera i.e. | C19: Azienda | D19: GG | E19: Totale i.e.
A20: PM Senior | B20: 930 | C20: Accenture | E20: =B20*D21 -> 0
A21: Senior Infrastructure Automation Specialist | B21: 500 | C21: Reply | E21: =B21*D22 -> 0
A23: Studio Fattibilità
A24: FTE | B24: Tariffa giornaliera i.e. | C24: Azienda | D24: GG | E24: Totale i.e.
A25: PM Junior | B25: 435 | C25: Reply | E25: =B25*D25 -> 0
A26: Cloud Solution Architecth | B26: 610 | C26: Reply | E26: =B26*D26 -> 0
A27: Cloud Engineer | B27: 450 | C27: Reply | E27: =B27*D27 -> 0
A29: Supporto Pipeline DevOps
A30: FTE | B30: Tariffa giornaliera i.e. | C30: Azienda | D30: GG | E30: Totale i.e.
A31: Enterprise solution Consultant | B31: 500 | C31: Imola Informatica | D31: 12 | E31: =B31*D31 -> 6000
A32: Supervisore e Coordinatore | B32: 500 | C32: Imola Informatica | D32: 1 | E32: =B32*D32 -> 500
A33: Architetto | B33: 450 | C33: Imola Informatica | D33: 5 | E33: =B33*D33 -> 2250
A34: PM | B34: 400 | C34: Imola Informatica | D34: 5 | E34: =B34*D34 -> 2000
A35: Analista funzionale | B35: 330 | C35: Imola Informatica | D35: 3 | E35: =B35*D35 -> 990
A36: Analista tecnico | B36: 280 | C36: Imola Informatica | D36: 3 | E36: =B36*D36 -> 840
E37: =SUM(E31:E36) -> 12580
A38: Change Enablers
A39: FTE | B39: Tariffa giornaliera i.e. | C39: Azienda | D39: GG | E39: Totale i.e.
A40: Infrastructure Automation Specialist | B40: 400 | C40: Reply | D40: 21 | E40: =B40*D40 -> 8400
A41: Senior Infrastructure Automation Specialist | B41: 500 | C41: Reply | D41: 4 | E41: =B41*D41 -> 2000
A42: System Administrator | B42: 430 | C42: Reply | D42: 32 | E42: =B42*D42 -> 13760
E43: =SUM(E40:E42) -> 24160

Sheet Fasce Budget CTO
A1: Di seguito il dettaglio esplicativo dei parametri considerati per fascia: la presenza di almeno uno di questi parametri caratterizza la fascia da attribuire al progetto
B3: NO IMPATTI CTO | C3: LIGHT | D3: MEDIUM | E3: COMPLESSO | F3: SPECIALE
A4: Esempio Progetto | B4: - | C4: Nuove funzioni su APP MOBILE | D4: Evoluzione DOL | E4: CORPORATE | F4: FREE/ Open Finance
A5: Budget Progettuale (k€, i.i.) | B5: - | C5: Fino a 500 | D5: 500 – 1.000 | E5: 1.000 – 5.000 | F5: > 5.000
A6: Durata progettuale | B6: - | C6: 1 – 6 mesi | D6: 7 – 9 mesi | E6: > 1 anno | F6: pluriennale
A7: Impatto architetturale/ Infrastrutturale | B7: NO | C7: SI | D7: SI | E7: SI | F7: SI
A8: Entità Impatto | B8: NA | C8: Limitato | D8: Moderato | E8: Considerevole | F8: Sostanziale
A9: Impatto Tecnologico | B9: NA | C9: In continuità con AS IS | D9: Evoluzioni tecnologica (no nuove) | E9: Evoluzione/ nuova tecnologia | F9: Cambio tecnologico
A10: Rischio sul Servizio | B10: NA | C10: Minimo | D10: Moderato | E10: Rilevante | F10: Radicale
A11: Pipeline | B11: NA | C11: Max 10 | D11: 11232 | E11: 30 - 60 | F11: > 60
A12: Numero Microservizi | B12: NA | C12: 0 – 15 nuovi container | D12: 16 – 30 nuovi container | E12: 31 – 100 nuovi container | F12: > 100 nuovi container
A13: Impatto Base Dati | B13: NA | C13: < 1 TB (Dip) | D13: 1 – 10 TB (Dip) | E13: 10 – 50 TB (Dip) | F13: > 50 TB (Dip)
C14: < 10 GB (Host) | D14: 10 – 50 GB (Host) | E14: 50 – 100 GB (Host) | F14: > 100 GB (Host)
A15: Potenza di calcolo | B15: NA | C15: 0 – 30 core | D15: 30 – 60 core | E15: 60 – 200 core | F15: > 200 core
A16: N° Batch schedulazioni | B16: NA | C16: 0 – 30 | D16: 30 - 60 | E16: 60 - 200 | F16: > 200
A17: Sistemi di monitoraggio | B17: NA | C17: Esistente (no action) | D17: SI | E17: SI | F17: SI
A18: Osservability | B18: NA | C18: Esistente (no action) | D18: SI | E18: SI | F18: SI
A19: Magnitudo test (Governance test) | B19: NA | C19: Fino a 100 Test Cases | D19: 100 – 1.000 Test Cases | E19: 1.000 – 10.000 Test Cases | F19: > 10.000 Test Cases
C20: Complessità: bassa | D20: Complessità: media | E20: Complessità: elevata | F20: Complessità: elevata
A21: Marco – stima CTO | B21: Nessuna macro-stima lato CTO | C21: 50 – 100 | D21: 100 - 200 | E21: 200 - 500 | F21: Macro- stima da determinare sulla base delle peculiarità
A22: (k€ ,i.i.) | C22: (20-40 Opex, 40 – 60 Capex) | D22: (40-90 Opex, 60-110 Capex) | E22: (90-275 Opex, 110-225 Capex)
A23: Opex annuale (ricorrente)

Sheet Budget allocato
B3: TIPOLOGIA | C3: DESCRIZIONE DELL’INTERVENTO | D3: IMPORTO | E3: IMPORTO | F3: Data messa in uso | G3: SOCIETA’ GRUPPO CA
D4: Q1 - Q2 | E4: Q3 - Q4
B5: Investimento IT
B10: TOTALE CAPEX
B11: Consulenze
B13: Onere progettuale IT
B17: Onere ricorrente
B19: TOTALE OPEX
B20: TOTALE | D20: =SUM(D5:D18) -> 0 | E20: =SUM(E5:E18) -> 0

Sheet ACN Listino licenze
B1: COSTO IVA | C1: 1.22
B3: Sistema operativo | C3: Prezzo unitario | D3: prezzo ivato | E3: costo dal secondo anno
B4: Windows Standard + SCCM (16 core) | C4: =144.18*16 -> 2306.88 | D4: =C4*$C$1 -> 2814.3936 | E4: =37.76*16 -> 604.16
B5: Windows Datacenter + SCCM (16 core) | C5: =680.28*16 -> 10884.48 | D5: =C5*$C$1 -> 13279.066 | E5: =168.84*16 -> 2701.44
B6: SCCM | C6: 898.56 | D6: =C6*$C$1 -> 1096.2432
B7: Linux Suse | C7: 1300 | D7: =C7*$C$1 -> 1586 | E7: =1586 -> 1586
B8: Linux Red Hat (host esx + Smart) Premium | C8: 919.4 | D8: =C8*$C$1 -> 1121.668 | E8: =C8 -> 919.4
B9: Linux Red Hat (host esx + Smart) Standard | C9: 695 | D9: =C9*$C$1 -> 847.9
B11: Virtualizzazione | C11: Prezzo unitario | D11: prezzo ivato | E11: costo dal secondo anno
B12: Vmware OEM | C12: 2295 | D12: =C12*$C$1 -> 2799.9 | E12: 458
B14: Monitoraggio | C14: Prezzo unitario | D14: prezzo ivato | E14: costo dal secondo anno
B15: Splunk (GB/day) - SubScription | C15: =420.62 -> 420.62 | D15: =C15*$C$1 -> 513.1564 | E15: =C15*1.22 -> 513.1564
B16: Dyntrace (HostUnit, copre 16 GB di RAM del server ) -SubScription (legacy mode) | C16: =951/1.22 -> 779.5082 | D16: =C16*$C$1 -> 951 | E16: =C16*1.22 -> 951
B17: Dynatrace SaaS - Full Stack Monitoring (1 GB / Year) | C17: =(372.31/100000)*24*365 -> 32.614356 | D17: =C17*$C$1 -> 39.789514 | E17: =C17*1.22 -> 39.789514
B18: Dynatrace SaaS -Infrastructure Monitoring (1 VM / Year) | C18: =(1488.85/100000)*24*365 -> 130.42326 | D18: =C18*$C$1 -> 159.11638 | E18: =C18*1.22 -> 159.11638
B19: Dynatrace SaaS -K8s Platform Monitoring (1 POD / Year) | C19: =(139/100000)*24*365 -> 12.1764 | D19: =C19*$C$1 -> 14.855208 | E19: =C19*1.22 -> 14.855208
B20: Dynatrace SaaS -Log Management & Analytics - Ingest & Process (1 GB ) | C20: =(1387/10000)*12*365 -> 607.506 | D20: =C20*$C$1 -> 741.15732 | E20: =C20*1.22 -> 741.15732
B21: Dynatrace SaaS -Log Management & Analytics - Retain (1 GB / Day ) | C21: =(486/1000000)*30 -> 0.01458 | D21: =C21*$C$1 -> 0.0177876 | E21: =C21*1.22 -> 0.0177876
B23: Front-end | C23: Prezzo unitario | D23: prezzo ivato | E23: costo dal secondo anno
B24: Subscription sharepoint | C24: 1484.49 | D24: =C24*$C$1 -> 1811.0778 | E24: =C24 -> 1484.49
B25: Jboss - standard (16 core preprod) | C25: 4100 | D25: =C25*1.22 -> 5002 | E25: =C25 -> 4100
B26: Jbos - premium (16 core prod) | C26: 6150 | D26: =C26*1.22 -> 7503 | E26: =C26 -> 6150
B27: websphere - PVU (1core=70PVU) | C27: 39.06 | D27: =C27*$C$1 -> 47.6532 | E27: =7.81 -> 7.81
B29: Database | C29: Prezzo unitario | D29: prezzo ivato | E29: costo dal secondo anno
B30: SQL server Enterprise (costo per 2 core) | C30: =2918*16 -> 46688 | D30: =C30*1.22 -> 56959.36 | E30: =2004*16 -> 32064
B32: InfoScale Veritas | C32: Prezzo unitario | D32: prezzo ivato | E32: costo dal secondo anno
B33: Infoscale | C33: 489.65 | D33: 597.373 | E33: =D33*25% -> 149.34325
B35: Schedulazione | C35: Prezzo unitario | D35: prezzo ivato | E35: costo dal secondo anno
B36: TWS a job | C36: =10.3/10 -> 1.03 | D36: =C36*$C$1 -> 1.2566 | E36: =2.06*1.22/10 -> 0.25132
B38: Alta Disponibilità | C38: Prezzo unitario | D38: prezzo ivato | E38: costo dal secondo anno
B39: SRM | C39: 4152.66 | D39: =C39*$C$1 -> 5066.2452 | E39: =830.53 -> 830.53
B40: HA RED HAT | C40: 319 | D40: =C40*$C$1 -> 389.18 | E40: =C40 -> 319
B41: HA RED HAT unlimited guest | C41: 996 | D41: =C41*$C$1 -> 1215.12 | E41: 1215.12
B43: Altro | C43: Prezzo unitario | D43: prezzo ivato | E43: costo dal secondo anno
B44: Certificato SSL | C44: 885 | D44: =C44*$C$1 -> 1079.7 | E44: =C44 -> 885
B45: MQ - PVU | C45: 22.04 | D45: 28.741847 | E45: =5.75 -> 5.75
B46: Mirantis - Prod | C46: =740/1.22 -> 606.55738 | D46: =C46*1.22 -> 740 | E46: =D46 -> 740
B47: Mirantis - DR | C47: =370/1.22 -> 303.27869 | D47: =C47*1.22 -> 370 | E47: =D47 -> 370
B48: Mirantis - PreProd | C48: =332/1.22 -> 272.13115 | D48: =C48*$C$1 -> 332 | E48: =D48 -> 332
B49: OpenShift - Prod | C49: 690.87 | D49: =C49*1.22 -> 842.8614 | E49: =D49 -> 842.8614
...

Sheet ACN Richieste
A1: Servizio 1 | B1: Input | C1: Sviluppo/Collaudo | D1: Parallelo | E1: Produzione
B2: Numero di pod on cloud | C2: 0 | D2: 0 | E2: 0
B3: Numero di pod on premise | C3: 0 | D3: 0 | E3: 0
B4: Dimensionamento pod on cloud (CPU e RAM)
B5: Dimensionamento pod on premise (CPU e RAM)
B6: Dimensionamento logging previsto al mese on cloud (in GB) | C6: 2GB | D6: 2GB | E6: 2GB
B7: Collaudo | C7: Parallelo | D7: Produzione | E7: DR | F7: Tot | G7: CPU Standard | H7: CPU Premium
A8: Server 4CPU | B8: 0 | C8: 0 | D8: 0 | E8: 0 | F8: 0 | G8: =(B8+C8+E8)*4 -> 0 | H8: =D8*4 -> 0
A9: Server 8 Cpu | C9: 0 | D9: 0 | E9: 0 | F9: =SUM(B9:E9) -> 0 | G9: =(B9+C9+E9)*8 -> 0 | H9: =D9*8 -> 0
A10: Spazio Disco | B10: 0 | C10: 0 | D10: 0 | F10: =SUM(B10:E10) -> 0
A11: Backup | D11: 0 | F11: =SUM(B11:E11) -> 0
A12: NameSpace | B12: 0 | C12: 0 | D12: 0 | E12: 0 | F12: =SUM(B12:E12) -> 0
A13: PodDepolyment | B13: 0 | C13: 0 | D13: 0 | E13: 0 | F13: =SUM(B13:E13) -> 0
A15: Servizio 2 | B15: Input | C15: Sviluppo/Collaudo | D15: Parallelo | E15: Produzione
B16: Dimensionamento storage | C16: 4GB | D16: 17GB | E16: 17GB
B17: Dimensionamento database | C17: 1GB | D17: 3GB | E17: 3GB
B18: numero di nodi | C18: 0 | D18: 0 | E18: 0
B19: Dimensionamento VM (CPU e RAM) | C19: 1 CPU - 4GB RAM | D19: 4 CPU – 16GB RAM | E19: 4 CPU – 16GB RAM
B20: Collaudo | C20: Parallelo | D20: Produzione | E20: DR | F20: Tot
A21: Server 4CPU | B21: 0 | C21: 0 | D21: 0 | F21: =SUM(B21:E21) -> 0
A22: Server 8 Cpu | F22: =SUM(B22:E22) -> 0
A23: Spazio Disco | B23: 0 | C23: 0 | D23: 0 | F23: =SUM(B23:E23) -> 0
A24: Backup | D24: 0 | F24: =SUM(B24:E24) -> 0
A25: NameSpace | F25: =SUM(B25:E25) -> 0
A26: PodDepolyment | F26: =SUM(B26:E26) -> 0
A27: Gestione Istanze Db | B27: 0 | C27: 0 | D27: 0 | F27: =SUM(B27:E27) -> 0
A29: Spazio Documenti
B30: Collaudo | C30: Parallelo | D30: Produzione | E30: DR
A31: Spazio Disco | B31: 0 | C31: 0 | D31: 0 | F31: =SUM(B31:E31) -> 0
A32: Backup | B32: 0 | C32: 0 | D32: 0 | F32: =SUM(B32:E32) -> 0
A34: Servizio 3 | B34: Input | C34: Sviluppo/Collaudo | D34: Parallelo | E34: Produzione
B35: Numero di pod on cloud | C35: 0 | D35: 0 | E35: 0
B36: Dimensionamento pod on cloud (CPU e RAM) | C36: 0 | D36: 0 | E36: 0
B37: Collaudo | C37: Parallelo | D37: Produzione | E37: DR | F37: Tot | G37: CPU Standard | H37: CPU Premium
A38: Server 4CPU | B38: 0 | C38: 0 | D38: 0 | E38: 0 | F38: =SUM(B38:E38) -> 0 | G38: =(B38+C38+E38)*4 -> 0 | H38: =D38*4 -> 0
A39: Server 8 Cpu | D39: 0 | E39: 0 | F39: =SUM(B39:E39) -> 0 | G39: =(B39+C39+E39)*4 -> 0 | H39: =D39*4 -> 0
A40: Spazio Disco | B40: 0 | C40: 0 | D40: 0 | F40: =SUM(B40:E40) -> 0
A41: Backup | D41: 0 | F41: =SUM(B41:E41) -> 0
A42: NameSpace | B42: 0 | C42: 0 | D42: 0 | E42: 0 | F42: =SUM(B42:E42) -> 0
A43: PodDepolyment | B43: 0 | C43: 0 | D43: 0 | E43: 0 | F43: =SUM(B43:E43) -> 0
...

Sheet ACN
A1: Device e/o servizi | B1: Tempo di fornitura | C1: Ciclo di vita (*) | D1: Caratteristiche | G1: Modello (ove disponibile) | H1: Costo Anno 1 AGO25-LUG26 | I1: Costo Anno 2 AGO26-LUG27 | J1: Costo Anno 3 AGO28-LUG29 | K1: Costo Anno 4 AGO30-LUG31 | L1: Costo Anno 5 AGO32-LUG33 | M1: Costo Anno 6 AGO26-LUG27 | N1: TOTALE | O1: TOTALE + IVA | P1: Costo Anno 1 reale | Q1: Costo Anno 2 reale | R1: Costo Anno 3 reale | S1: Costo Anno 4 reale | T1: Costo Anno 5 reale | U1: Costo Anno 6 reale | V1: Costo Anno 7 reale | W1: TOTALE reale + IVA
D2: #CPU | E2: RAM | F2: Tera
F3: byte
A4: Server virtuale - 4 vCore | B4: 6 ore lavorative | C4: 5 anni | D4: 4 | E4: 16 | G4: Senza OS, senza Vmware | H4: 684.05 | I4: 623.84 | J4: 586.23 | K4: 562.94 | L4: 551.8 | M4: 551.8 | N4: =SUM(H4:M4) -> 3560.66 | O4: =N4*1.22 -> 4344.0052 | P4: =IF(TODAY()<DATEVALUE("31/07/2022"),H4,0) -> #VALUE! | Q4: =IF(TODAY()<DATEVALUE("31/07/2023"),I4,0) -> #VALUE! | R4: =IF(TODAY()<DATEVALUE("31/07/2024"),J4,0) -> #VALUE! | S4: =IF(TODAY()<DATEVALUE("31/07/2025"),K4,0) -> #VALUE! | T4: =IF(TODAY()<DATEVALUE("31/07/2026"),L4,0) -> #VALUE! | U4: =IF(TODAY()<DATEVALUE("31/07/2027"),M4,0) -> #VALUE! | V4: =IF(TODAY()<DATEVALUE("31/07/2027"),N4,0) -> #VALUE! | W4: =SUM(P4:V4)*1.22 -> #VALUE!
A5: Server virtuale - 8 vCore | B5: 6 ore lavorative | C5: 5 anni | D5: 8 | E5: 32 | G5: Senza OS, senza Vmware | H5: 862.08 | I5: 797.3 | J5: 759.68 | K5: 736.39 | L5: 725.25 | M5: 725.25 | N5: =SUM(H5:M5) -> 4605.95 | O5: =N5*1.22 -> 5619.259 | P5: =IF(TODAY()<DATEVALUE("31/07/2022"),H5,0) -> #VALUE! | Q5: =IF(TODAY()<DATEVALUE("31/07/2023"),I5,0) -> #VALUE! | R5: =IF(TODAY()<DATEVALUE("31/07/2024"),J5,0) -> #VALUE! | S5: =IF(TODAY()<DATEVALUE("31/07/2025"),K5,0) -> #VALUE! | T5: =IF(TODAY()<DATEVALUE("31/07/2026"),L5,0) -> #VALUE! | U5: =IF(TODAY()<DATEVALUE("31/07/2027"),M5,0) -> #VALUE! | V5: =IF(TODAY()<DATEVALUE("31/07/2027"),N5,0) -> #VALUE! | W5: =SUM(P5:V5)*1.22 -> #VALUE!
A6: Backup – Front-end | B6: 3 Giorni Lavorativi | C6: 5 anni | F6: 1 | H6: 2184.42 | I6: 465.93 | J6: 461.52 | K6: 457.12 | L6: 452.71 | M6: 2162.4 | N6: =SUM(H6:M6) -> 6184.1 | O6: =N6*1.22 -> 7544.602 | P6: =IF(TODAY()<DATEVALUE("31/07/2022"),H6,0) -> #VALUE! | Q6: =IF(TODAY()<DATEVALUE("31/07/2023"),I6,0) -> #VALUE! | R6: =IF(TODAY()<DATEVALUE("31/07/2024"),J6,0) -> #VALUE! | S6: =IF(TODAY()<DATEVALUE("31/07/2025"),K6,0) -> #VALUE! | T6: =IF(TODAY()<DATEVALUE("31/07/2026"),L6,0) -> #VALUE! | U6: =IF(TODAY()<DATEVALUE("31/07/2027"),M6,0) -> #VALUE! | V6: =IF(TODAY()<DATEVALUE("31/07/2027"),N6,0) -> #VALUE! | W6: =SUM(P6:V6)*1.22 -> #VALUE!
A7: Backup – Back-end | B7: 3 Giorni Lavorativi | C7: 5 anni | F7: 1 | H7: 201.55 | I7: 118.25 | J7: 116.24 | K7: 114.23 | L7: 112.21 | M7: 191.49 | N7: =SUM(H7:M7) -> 853.97 | O7: =N7*1.22 -> 1041.8434 | P7: =IF(TODAY()<DATEVALUE("31/07/2022"),H7,0) -> #VALUE! | Q7: =IF(TODAY()<DATEVALUE("31/07/2023"),I7,0) -> #VALUE! | R7: =IF(TODAY()<DATEVALUE("31/07/2024"),J7,0) -> #VALUE! | S7: =IF(TODAY()<DATEVALUE("31/07/2025"),K7,0) -> #VALUE! | T7: =IF(TODAY()<DATEVALUE("31/07/2026"),L7,0) -> #VALUE! | U7: =IF(TODAY()<DATEVALUE("31/07/2027"),M7,0) -> #VALUE! | V7: =IF(TODAY()<DATEVALUE("31/07/2027"),N7,0) -> #VALUE! | W7: =SUM(P7:V7)*1.22 -> #VALUE!
A8: Storage - SSD | B8: 3 Giorni Lavorativi | C8: 3 anni | F8: 1 | G8: Replicato, non compresso | H8: 868.35 | I8: 834.31 | J8: 819 | K8: 809.52 | L8: 804.98 | M8: 804.98 | N8: =SUM(H8:M8) -> 4941.14 | O8: =N8*1.22 -> 6028.1908 | P8: =IF(TODAY()<DATEVALUE("31/07/2022"),H8,0) -> #VALUE! | Q8: =IF(TODAY()<DATEVALUE("31/07/2023"),I8,0) -> #VALUE! | R8: =IF(TODAY()<DATEVALUE("31/07/2024"),J8,0) -> #VALUE! | S8: =IF(TODAY()<DATEVALUE("31/07/2025"),K8,0) -> #VALUE! | T8: =IF(TODAY()<DATEVALUE("31/07/2026"),L8,0) -> #VALUE! | U8: =IF(TODAY()<DATEVALUE("31/07/2027"),M8,0) -> #VALUE! | V8: =IF(TODAY()<DATEVALUE("31/07/2027"),N8,0) -> #VALUE! | W8: =SUM(P8:V8)*1.22 -> #VALUE!
A9: Storage - SSD non replicati | B9: 3 Giorni Lavorativi | C9: 3 anni | F9: 1 | G9: Non replicato, non compresso | H9: 553.22 | I9: 524.87 | J9: 509.56 | K9: 500.08 | L9: 495.55 | M9: 495.55 | N9: =SUM(H9:M9) -> 3078.83 | O9: =N9*1.22 -> 3756.1726 | P9: =IF(TODAY()<DATEVALUE("31/07/2022"),H9,0) -> #VALUE! | Q9: =IF(TODAY()<DATEVALUE("31/07/2023"),I9,0) -> #VALUE! | R9: =IF(TODAY()<DATEVALUE("31/07/2024"),J9,0) -> #VALUE! | S9: =IF(TODAY()<DATEVALUE("31/07/2025"),K9,0) -> #VALUE! | T9: =IF(TODAY()<DATEVALUE("31/07/2026"),L9,0) -> #VALUE! | U9: =IF(TODAY()<DATEVALUE("31/07/2027"),M9,0) -> #VALUE! | V9: =IF(TODAY()<DATEVALUE("31/07/2027"),N9,0) -> #VALUE! | W9: =SUM(P9:V9)*1.22 -> #VALUE!
A10: OS gestione Linux / Windows | B10: 3 Giorni Lavorativi | C10: 1 anno | F10: 1 | G10: Gestione OS | H10: 498.93 | I10: 443.29 | J10: 405.68 | K10: 382.39 | L10: 371.25 | M10: 371.25 | N10: =SUM(H10:M10) -> 2472.79 | O10: =N10*1.22 -> 3016.8038 | P10: =IF(TODAY()<DATEVALUE("31/07/2022"),H10,0) -> #VALUE! | Q10: =IF(TODAY()<DATEVALUE("31/07/2023"),I10,0) -> #VALUE! | R10: =IF(TODAY()<DATEVALUE("31/07/2024"),J10,0) -> #VALUE! | S10: =IF(TODAY()<DATEVALUE("31/07/2025"),K10,0) -> #VALUE! | T10: =IF(TODAY()<DATEVALUE("31/07/2026"),L10,0) -> #VALUE! | U10: =IF(TODAY()<DATEVALUE("31/07/2027"),M10,0) -> #VALUE! | V10: =IF(TODAY()<DATEVALUE("31/07/2027"),N10,0) -> #VALUE! | W10: =SUM(P10:V10)*1.22 -> #VALUE!
A11: Database Oracle (non RAC) - gestione istanze (*) | B11: 5 Giorni Lavorativi | C11: 1 anno | G11: Operation - management DBMS instance | H11: 1062.29 | I11: 943 | J11: 863.74 | K11: 814.17 | L11: 790.43 | M11: 790.43 | N11: =SUM(H11:M11) -> 5264.06 | O11: =N11*1.22 -> 6422.1532 | P11: =IF(TODAY()<DATEVALUE("31/07/2022"),H11,0) -> #VALUE! | Q11: =IF(TODAY()<DATEVALUE("31/07/2023"),I11,0) -> #VALUE! | R11: =IF(TODAY()<DATEVALUE("31/07/2024"),J11,0) -> #VALUE! | S11: =IF(TODAY()<DATEVALUE("31/07/2025"),K11,0) -> #VALUE! | T11: =IF(TODAY()<DATEVALUE("31/07/2026"),L11,0) -> #VALUE! | U11: =IF(TODAY()<DATEVALUE("31/07/2027"),M11,0) -> #VALUE! | V11: =IF(TODAY()<DATEVALUE("31/07/2027"),N11,0) -> #VALUE! | W11: =SUM(P11:V11)*1.22 -> #VALUE!
A12: Database Ms SQL - gestione istanze (*) | B12: 5 Giorni Lavorativi | C12: 1 anno | G12: Operation - management DBMS instance | H12: 524.64 | I12: 466.14 | J12: 426.58 | K12: 402.09 | L12: 390.38 | M12: 390.38 | N12: =SUM(H12:M12) -> 2600.21 | O12: =N12*1.22 -> 3172.2562 | P12: =IF(TODAY()<DATEVALUE("31/07/2022"),H12,0) -> #VALUE! | Q12: =IF(TODAY()<DATEVALUE("31/07/2023"),I12,0) -> #VALUE! | R12: =IF(TODAY()<DATEVALUE("31/07/2024"),J12,0) -> #VALUE! | S12: =IF(TODAY()<DATEVALUE("31/07/2025"),K12,0) -> #VALUE! | T12: =IF(TODAY()<DATEVALUE("31/07/2026"),L12,0) -> #VALUE! | U12: =IF(TODAY()<DATEVALUE("31/07/2027"),M12,0) -> #VALUE! | V12: =IF(TODAY()<DATEVALUE("31/07/2027"),N12,0) -> #VALUE! | W12: =SUM(P12:V12)*1.22 -> #VALUE!
A13: DB2 Blu - gestione istanze | B13: 5 Giorni Lavorativi | C13: 1 anno | G13: Operation - management DBMS instance | H13: 699.52 | I13: 621.52 | J13: 568.78 | K13: 536.13 | L13: 520.51 | M13: 520.51 | N13: =SUM(H13:M13) -> 3466.97 | O13: =N13*1.22 -> 4229.7034 | P13: =IF(TODAY()<DATEVALUE("31/07/2022"),H13,0) -> #VALUE! | Q13: =IF(TODAY()<DATEVALUE("31/07/2023"),I13,0) -> #VALUE! | R13: =IF(TODAY()<DATEVALUE("31/07/2024"),J13,0) -> #VALUE! | S13: =IF(TODAY()<DATEVALUE("31/07/2025"),K13,0) -> #VALUE! | T13: =IF(TODAY()<DATEVALUE("31/07/2026"),L13,0) -> #VALUE! | U13: =IF(TODAY()<DATEVALUE("31/07/2027"),M13,0) -> #VALUE! | V13: =IF(TODAY()<DATEVALUE("31/07/2027"),N13,0) -> #VALUE! | W13: =SUM(P13:V13)*1.22 -> #VALUE!
A14: NoSQLDB - gestione istanze | B14: 5 Giorni Lavorativi | C14: 1 anno | G14: Operation - management DBMS instance | H14: 699.52 | I14: 621.52 | J14: 568.78 | K14: 536.13 | L14: 520.51 | M14: 520.51 | N14: =SUM(H14:M14) -> 3466.97 | O14: =N14*1.22 -> 4229.7034 | P14: =IF(TODAY()<DATEVALUE("31/07/2022"),H14,0) -> #VALUE! | Q14: =IF(TODAY()<DATEVALUE("31/07/2023"),I14,0) -> #VALUE! | R14: =IF(TODAY()<DATEVALUE("31/07/2024"),J14,0) -> #VALUE! | S14: =IF(TODAY()<DATEVALUE("31/07/2025"),K14,0) -> #VALUE! | T14: =IF(TODAY()<DATEVALUE("31/07/2026"),L14,0) -> #VALUE! | U14: =IF(TODAY()<DATEVALUE("31/07/2027"),M14,0) -> #VALUE! | V14: =IF(TODAY()<DATEVALUE("31/07/2027"),N14,0) -> #VALUE! | W14: =SUM(P14:V14)*1.22 -> #VALUE!
A15: Middleware IIS / Apache - gestione istanze | B15: 5 Giorni Lavorativi | C15: 1 anno | G15: Operation - management Middleware instance | H15: 330.8 | I15: 293.91 | J15: 268.97 | K15: 253.53 | L15: 246.14 | M15: 246.14 | N15: =SUM(H15:M15) -> 1639.49 | O15: =N15*1.22 -> 2000.1778 | P15: =IF(TODAY()<DATEVALUE("31/07/2022"),H15,0) -> #VALUE! | Q15: =IF(TODAY()<DATEVALUE("31/07/2023"),I15,0) -> #VALUE! | R15: =IF(TODAY()<DATEVALUE("31/07/2024"),J15,0) -> #VALUE! | S15: =IF(TODAY()<DATEVALUE("31/07/2025"),K15,0) -> #VALUE! | T15: =IF(TODAY()<DATEVALUE("31/07/2026"),L15,0) -> #VALUE! | U15: =IF(TODAY()<DATEVALUE("31/07/2027"),M15,0) -> #VALUE! | V15: =IF(TODAY()<DATEVALUE("31/07/2027"),N15,0) -> #VALUE! | W15: =SUM(P15:V15)*1.22 -> #VALUE!
A16: Middleware Tomcat/Jboss - gestione istanze | B16: 5 Giorni Lavorativi | C16: 1 anno | G16: Operation - management Middleware instance | H16: 441.06 | I16: 391.88 | J16: 358.62 | K16: 338.04 | L16: 328.19 | M16: 328.19 | N16: =SUM(H16:M16) -> 2185.98 | O16: =N16*1.22 -> 2666.8956 | P16: =IF(TODAY()<DATEVALUE("31/07/2022"),H16,0) -> #VALUE! | Q16: =IF(TODAY()<DATEVALUE("31/07/2023"),I16,0) -> #VALUE! | R16: =IF(TODAY()<DATEVALUE("31/07/2024"),J16,0) -> #VALUE! | S16: =IF(TODAY()<DATEVALUE("31/07/2025"),K16,0) -> #VALUE! | T16: =IF(TODAY()<DATEVALUE("31/07/2026"),L16,0) -> #VALUE! | U16: =IF(TODAY()<DATEVALUE("31/07/2027"),M16,0) -> #VALUE! | V16: =IF(TODAY()<DATEVALUE("31/07/2027"),N16,0) -> #VALUE! | W16: =SUM(P16:V16)*1.22 -> #VALUE!
A17: Middleware WebSphere - gestione istanze | B17: 5 Giorni Lavorativi | C17: 1 anno | G17: Operation - management Middleware instance | H17: 551.33 | I17: 489.85 | J17: 448.28 | K17: 422.55 | L17: 410.24 | M17: 410.24 | N17: =SUM(H17:M17) -> 2732.49 | O17: =N17*1.22 -> 3333.6378 | P17: =IF(TODAY()<DATEVALUE("31/07/2022"),H17,0) -> #VALUE! | Q17: =IF(TODAY()<DATEVALUE("31/07/2023"),I17,0) -> #VALUE! | R17: =IF(TODAY()<DATEVALUE("31/07/2024"),J17,0) -> #VALUE! | S17: =IF(TODAY()<DATEVALUE("31/07/2025"),K17,0) -> #VALUE! | T17: =IF(TODAY()<DATEVALUE("31/07/2026"),L17,0) -> #VALUE! | U17: =IF(TODAY()<DATEVALUE("31/07/2027"),M17,0) -> #VALUE! | V17: =IF(TODAY()<DATEVALUE("31/07/2027"),N17,0) -> #VALUE! | W17: =SUM(P17:V17)*1.22 -> #VALUE!
A18: Middleware WebLogic - gestione istanze | B18: 5 Giorni Lavorativi | C18: 1 anno | G18: Operation - management Middleware instance | H18: 661.59 | I18: 587.82 | J18: 537.94 | K18: 507.06 | L18: 492.29 | M18: 492.29 | N18: =SUM(H18:M18) -> 3278.99 | O18: =N18*1.22 -> 4000.3678 | P18: =IF(TODAY()<DATEVALUE("31/07/2022"),H18,0) -> #VALUE! | Q18: =IF(TODAY()<DATEVALUE("31/07/2023"),I18,0) -> #VALUE! | R18: =IF(TODAY()<DATEVALUE("31/07/2024"),J18,0) -> #VALUE! | S18: =IF(TODAY()<DATEVALUE("31/07/2025"),K18,0) -> #VALUE! | T18: =IF(TODAY()<DATEVALUE("31/07/2026"),L18,0) -> #VALUE! | U18: =IF(TODAY()<DATEVALUE("31/07/2027"),M18,0) -> #VALUE! | V18: =IF(TODAY()<DATEVALUE("31/07/2027"),N18,0) -> #VALUE! | W18: =SUM(P18:V18)*1.22 -> #VALUE!
A19: F5 i10800 con WAF | B19: 35 Giorni Lavorativi | C19: NA | G19: Fornitura e gestione di 1 contesto virtuale con 2vCore (Virtual Core) suddiviso su 4 apparati hardware (1 active e 3 in stand-by) | H19: 60075.47 | I19: 60075.47 | J19: 60075.47 | K19: 60075.47 | L19: 60075.47 | M19: 60075.47 | N19: =SUM(H19:M19) -> 360452.82 | O19: =N19*1.22 -> 439752.44 | P19: =IF(TODAY()<DATEVALUE("31/07/2022"),H19,0) -> #VALUE! | Q19: =IF(TODAY()<DATEVALUE("31/07/2023"),I19,0) -> #VALUE! | R19: =IF(TODAY()<DATEVALUE("31/07/2024"),J19,0) -> #VALUE! | S19: =IF(TODAY()<DATEVALUE("31/07/2025"),K19,0) -> #VALUE! | T19: =IF(TODAY()<DATEVALUE("31/07/2026"),L19,0) -> #VALUE! | U19: =IF(TODAY()<DATEVALUE("31/07/2027"),M19,0) -> #VALUE! | V19: =IF(TODAY()<DATEVALUE("31/07/2027"),N19,0) -> #VALUE! | W19: =SUM(P19:V19)*1.22 -> #VALUE!
A20: Middleware Kubernates -Gestione Pod Deployment | H20: 251 | I20: 251 | J20: 251 | K20: 251 | L20: 251 | M20: 251 | N20: 251 | O20: 251 | Q20: =IF(TODAY()<DATEVALUE("31/07/2023"),I20,0) -> #VALUE!
A21: Middleware Kubernates -Gestione Namespace | H21: 532 | I21: 532 | J21: 532 | K21: 532 | L21: 532 | M21: 532 | N21: 532 | O21: 532
A22: OCPu | B22: 2 | H22: 29164 | I22: 29164 | J22: 28608.49 | K22: 28608.49 | L22: 28608.49 | M22: 28608.49
A23: TB Oracle exadtaa | B23: 30 | H23: 32901.62 | I23: 32901.62 | J23: 32274.92 | K23: 32274.92 | L23: 32274.92 | M23: 32274.92
A25: ATTENZIONE NOTE/ESEMPI
A26: (*) La logica di pricing prevede un prezzo per singolo DB (MSSQL) o Schema (Oracle)
A27: La gestione del OS è compresa nella voce server virtuale e fisico. Mentre per quanto riguarda la voce corrispettiva a Catalogo “OS gestione Linux/Windows”, questa fa riferimento ad una casistica di reinstallazione e gestione dell'OS su un server esistente il cui HW non è fornito da Accenture ma CAGS (caso raro).
A28: Se chiedo spazio disco di 1 TB, devo anche sommare entrambe le voci dei backup ovvero 1 TB SSD di dati costa il primo anno: 868,35 + 2.184,42 + 201,55
A31: anni alla fine del contratto | B31: =YEAR("31/7/2031")-YEAR(TODAY()) -> #VALUE!
A32: anni da considerare ma manutenzione | B32: =B31-1 -> #VALUE!

Sheet ACN Cloud
A1: Ambito | B1: Tecnologie | C1: Unità di misura | D1: AWS | E1: GCP | F1: Azure | G1: Voce | H1: Canone Annuo
A2: Container | B2: Managed Kubernetes | C2: N° di cluster | D2: EKS | E2: GKE | F2: AKS | G2: Operation | H2: 3233.04
A3: Container | B3: N di namespace | C3: N di namespace | D3: EKS | E3: GKE | F3: AKS | G3: Operation | H3: 206.25
A4: Container | B4: N di POD Deployment | C4: N di POD Deployment | D4: EKS | E4: GKE | F4: AKS | G4: Operation | H4: 93.75
A5: VM | B5: Virtual Machines | C5: N° di VM | D5: EC2 | E5: Compute Engine | F5: VMs | G5: Operation | H5: 568.75
A6: Storage | B6: Object Based Storage | C6: N° di OBS | D6: S3 | E6: Cloud Storage | F6: BLOB Storage | G6: Operation | H6: 0
A7: Storage | B7: Disks | C7: N° di dischi | D7: Elastic Block Store | E7: Persistent Disk | F7: Disks | G7: Operation | H7: 0
A8: Database | B8: PostgreSQL EDB on Microservice | C8: N° di istanze (DB Engine) | D8: Rosa, EKS | E8: OCD, GKE | F8: ARO, AKS | G8: Operation | H8: 537.5
A9: Database | B9: PostgreSQL - PaaS | C9: N° di risorsa cloud | D9: RDS, Aurora | E9: CloudSQL, AlloyDB | F9: DB for PostgreSQL, | G9: Operation | H9: 537.5
A10: Database | B10: SQL Server - IaaS | C10: N° di istanze (DB Engine) | D10: VM | E10: VM | F10: VM | G10: Operation | H10: 625
A11: Database | B11: SQL Server - PaaS | C11: N° di istanze (DB Engine) | D11: RDS | E11: Cloud SQL | F11: SQL Database | G11: Operation | H11: 537.5
A12: Database | B12: MySQL - IaaS | C12: N° di istanze (DB Engine) | D12: VM | E12: VM | F12: VM | G12: Operation | H12: 624.42
A13: Database | B13: MySQL - PaaS | C13: N° di istanze (DB Engine) | D13: RDS, Aurora | E13: CloudSQL, AlloyDB | F13: DB for MySQL, | G13: Operation | H13: 537.5
... A20: Security Management | B20: Security Posture Management Platform | C20: N° di organization | D20: AWS Security HUB | E20: GCP Security | F20: Azure Security Center | G20: Operation | H20: 8100
A21: Database | B21: NoSQL - PaaS | C21: N° di istanze (DB Engine) | D21: DynamoDB | E21: Firestore, Datastore | F21: CosmosDB | G21: Operation | H21: 0 | I21: Da valutare in fase di revisione prezzi (*)
A22: Storage | B22: SMB file share | C22: N. file share | D22: FSx | E22: Filestore | F22: Files | G22: Operation | H22: 0 | I22: Da valutare in fase di revisione prezzi (*)

Sheet ACN Decommisioning
A1: Device e/o servizi | B1: Tempo di fornitura | C1: Ciclo di vita (*) | D1: Caratteristiche | G1: Modello (ove disponibile) | H1: Costo Anno 1 AGO21-LUG22 | I1: Costo Anno 2 AGO22-LUG23 | J1: Costo Anno 3 AGO23-LUG24 | K1: Costo Anno 4 AGO24-LUG25 | L1: Costo Anno 5 AGO25-LUG26 | M1: Costo Anno 6 AGO26-LUG27 | N1: Costo Anno 7 AGO27-LUG28 | O1: Costo Anno 8 AGO28-LUG29 | P1: Costo Anno 9 AGO29-LUG30 | Q1: Costo Anno 10 AGO30-LUG31 | R1: TOTALE | S1: TOTALE + IVA
D2: #CPU | E2: RAM | F2: Tera
F3: byte
A4: Server fisico - 32 Core | B4: 35 Giorni Lavorativi | C4: 5 anni | D4: 32 | E4: 512 | G4: Senza OS | H4: -424.42 | I4: -387.94 | J4: -363.27 | K4: -348 | L4: -340.7 | M4: -340.7 | N4: -333.4 | O4: -319.44 | P4: -300.04 | Q4: -276.78 | R4: =SUM(H4:Q4) -> -3434.69 | S4: =R4*1.22 -> -4190.3218
A5: Server virtuale - 4 vCore | B5: 6 ore lavorative | C5: 5 anni | D5: 4 | E5: 16 | G5: Senza OS, senza Vmware | H5: -513.58 | I5: -487.07 | J5: -456.98 | K5: -438.35 | L5: -429.44 | M5: -429.44 | N5: -420.53 | O5: -403.5 | P5: -379.83 | Q5: -351.45 | R5: =SUM(H5:Q5) -> -4310.17 | S5: =R5*1.22 -> -5258.4074 | T5: =H5+ACN!H4 -> 170.47
A6: Server virtuale - 8 vCore | B6: 6 ore lavorative | C6: 5 anni | D6: 8 | E6: 32 | G6: Senza OS, senza Vmware | H6: -568.34 | I6: -613.83 | J6: -583.74 | K6: -565.11 | L6: -556.2 | M6: -556.2 | N6: -547.29 | O6: -530.26 | P6: -506.59 | Q6: -478.21 | R6: =SUM(H6:Q6) -> -5505.77 | S6: =R6*1.22 -> -6717.0394 | T6: =H6+ACN!H5 -> 293.74
A7: Backup – Front-end | B7: 3 Giorni Lavorativi | C7: 5 anni | F7: 1 | H7: -133.64 | I7: -130.33 | J7: -127.03 | K7: -123.73 | L7: -120.42 | M7: -117.12 | N7: -113.82 | O7: -110.51 | P7: -107.21 | Q7: -103.91 | R7: =SUM(H7:Q7) -> -1187.72 | S7: =R7*1.22 -> -1449.0184 | T7: =-H7 -> 133.64
A8: Backup – Back-end | B8: 3 Giorni Lavorativi | C8: 5 anni | F8: 1 | H8: -58.09 | I8: -56.58 | J8: -55.07 | K8: -53.56 | L8: -52.05 | M8: -50.54 | N8: -49.03 | O8: -47.52 | P8: -46.01 | Q8: -44.5 | R8: =SUM(H8:Q8) -> -512.95 | S8: =R8*1.22 -> -625.799 | T8: =-H8 -> 58.09
A9: Storage - SSD | B9: 3 Giorni Lavorativi | C9: 3 anni | F9: 1 | G9: Replicato, non compresso | H9: -621.01 | I9: -604.02 | J9: -592.54 | K9: -585.43 | L9: -582.03 | M9: -582.03 | N9: -578.63 | O9: -572.13 | P9: -563.1 | Q9: -552.27 | R9: =SUM(H9:Q9) -> -5833.19 | S9: =R9*1.22 -> -7116.4918 | T9: =H9+ACN!H8 -> 247.34
A10: Storage - SSD non replicati | B10: 3 Giorni Lavorativi | C10: 3 anni | F10: 1 | G10: Non replicato, non compresso | H10: -399.79 | I10: -382.8 | J10: -371.82 | K10: -364.21 | L10: -360.81 | M10: -360.81 | N10: -357.41 | O10: -350.91 | P10: -341.87 | Q10: -331.04 | R10: =SUM(H10:Q10) -> -3621.47 | S10: =R10*1.22 -> -4418.1934
A11: OS gestione Linux / Windows | B11: 3 Giorni Lavorativi | C11: 1 anno | F11: 1 | G11: Gestione OS | H11: -399.15 | I11: 0 | J11: 0 | K11: 0 | L11: 0 | M11: 0 | N11: 0 | O11: 0 | P11: 0 | Q11: 0 | R11: =SUM(H11:Q11) -> -399.15 | S11: =R11*1.22 -> -486.963
